<?xml version="1.0" ?>
<robot name="walkie2" xmlns:xacro="http://www.ros.org/wiki/xacro">

<xacro:include filename="$(find walkie2_description)/urdf/materials.xacro" />
<xacro:include filename="$(find walkie2_description)/urdf/walkie2.trans" />
<xacro:include filename="$(find walkie2_description)/urdf/walkie2.gazebo" />
<xacro:include filename="$(find cr3_lowlevel_pkg)/urdf/cr3_robot_w_gripper_for_walkie2.xacro" />

<link name="base_footprint"/>

<joint name="base_joint" type="fixed">
  <origin rpy="0 0 0" xyz="0 0 0"/>
  <parent link="base_footprint"/>
  <child link="base_link"/>
</joint>

<link name="base_link">
  <inertial>
    <origin xyz="-0.1608928311021478 -5.96990322223803e-06 0.5834834631581107" rpy="0 0 0"/>
    <mass value="952.3993400032292"/>
    <inertia ixx="141.167931" iyy="139.78051" izz="23.866384" ixy="-5.5e-05" iyz="0.005153" ixz="12.651599"/>
  </inertial>
  <visual>
    <origin xyz="0 0 0" rpy="0 0 0"/>
    <geometry>
      <mesh filename="package://walkie2_description/meshes/base_link.stl" scale="0.001 0.001 0.001"/>
    </geometry>
    <material name="silver"/>
  </visual>
  <collision>
    <origin xyz="0 0 0" rpy="0 0 0"/>
    <geometry>
      <mesh filename="package://walkie2_description/meshes/base_link.stl" scale="0.001 0.001 0.001"/>
    </geometry>
  </collision>
</link>

<link name="right_wheel">
  <inertial>
    <origin xyz="2.128852395337864e-15 0.03612818166282045 6.938893903907228e-17" rpy="0 0 0"/>
    <mass value="12.73279410998368"/>
    <inertia ixx="0.02996" iyy="0.051127" izz="0.02996" ixy="-0.0" iyz="0.0" ixz="0.0"/>
  </inertial>
  <visual>
    <origin xyz="0.0 -0.194 -0.098" rpy="0 0 0"/>
    <geometry>
      <mesh filename="package://walkie2_description/meshes/RM_1.stl" scale="0.001 0.001 0.001"/>
    </geometry>
    <material name="silver"/>
  </visual>
  <collision>
    <origin xyz="0.0 -0.194 -0.098" rpy="0 0 0"/>
    <geometry>
      <mesh filename="package://walkie2_description/meshes/RM_1.stl" scale="0.001 0.001 0.001"/>
    </geometry>
  </collision>
</link>

<link name="left_wheel">
  <inertial>
    <origin xyz="-2.2204515407301662e-15 -0.049029818337179676 6.938893903907228e-17" rpy="0 0 0"/>
    <mass value="12.73279410998368"/>
    <inertia ixx="0.02996" iyy="0.051127" izz="0.02996" ixy="0.0" iyz="0.0" ixz="0.0"/>
  </inertial>
  <visual>
    <origin xyz="0.0 0.194 -0.098" rpy="0 0 0"/>
    <geometry>
      <mesh filename="package://walkie2_description/meshes/LM_1.stl" scale="0.001 0.001 0.001"/>
    </geometry>
    <material name="silver"/>
  </visual>
  <collision>
    <origin xyz="0.0 0.194 -0.098" rpy="0 0 0"/>
    <geometry>
      <mesh filename="package://walkie2_description/meshes/LM_1.stl" scale="0.001 0.001 0.001"/>
    </geometry>
  </collision>
</link>

<link name="hokuyo">
  <inertial>
    <origin xyz="-5.551115123125783e-17 -6.194138613915643e-18 0.009128499999999984" rpy="0 0 0"/>
    <mass value="0.18009801922048976"/>
    <inertia ixx="2.3e-05" iyy="2.3e-05" izz="3.6e-05" ixy="0.0" iyz="-0.0" ixz="-0.0"/>
  </inertial>
  <visual>
    <origin xyz="-0.197 0.0 -0.1955" rpy="0 0 0"/>
    <geometry>
      <mesh filename="package://walkie2_description/meshes/lidar_1.stl" scale="0.001 0.001 0.001"/>
    </geometry>
    <material name="silver"/>
  </visual>
  <collision>
    <origin xyz="-0.197 0.0 -0.1955" rpy="0 0 0"/>
    <geometry>
      <mesh filename="package://walkie2_description/meshes/lidar_1.stl" scale="0.001 0.001 0.001"/>
    </geometry>
  </collision>
</link>

<link name="base_cr3">
  <inertial>
    <origin xyz="0.1214215 -1.486984513226704e-17 -0.022599999999999953" rpy="0 0 0"/>
    <mass value="14.169925233606989"/>
    <inertia ixx="0.034347" iyy="0.072049" izz="0.101571" ixy="0.0" iyz="0.0" ixz="0.0"/>
  </inertial>
  <visual>
    <origin xyz="0.016306 -0.0 -0.7855" rpy="0 0 0"/>
    <geometry>
      <mesh filename="package://walkie2_description/meshes/CR3base_1.stl" scale="0.001 0.001 0.001"/>
    </geometry>
    <material name="silver"/>
  </visual>
  <collision>
    <origin xyz="0.016306 -0.0 -0.7855" rpy="0 0 0"/>
    <geometry>
      <mesh filename="package://walkie2_description/meshes/CR3base_1.stl" scale="0.001 0.001 0.001"/>
    </geometry>
  </collision>
</link>

<link name="realsense_yaw">
  <inertial>
    <origin xyz="-0.009267873664598997 -0.009584201347951788 0.0168296234143277" rpy="0 0 0"/>
    <mass value="0.52273509412428"/>
    <inertia ixx="0.001265" iyy="0.000145" izz="0.001315" ixy="0.000132" iyz="1.4e-05" ixz="7e-06"/>
  </inertial>
  <visual>
    <origin xyz="0.189306 -0.0 -1.463" rpy="0 0 0"/>
    <geometry>
      <mesh filename="package://walkie2_description/meshes/realsense_yaw.stl" scale="0.001 0.001 0.001"/>
    </geometry>
    <material name="steel_satin"/>
  </visual>
  <collision>
    <origin xyz="0.189306 -0.0 -1.463" rpy="0 0 0"/>
    <geometry>
      <mesh filename="package://walkie2_description/meshes/realsense_yaw.stl" scale="0.001 0.001 0.001"/>
    </geometry>
  </collision>
</link>

<link name="realsense_pitch">
  <inertial>
    <origin xyz="-1.1102230246251565e-16 0.050000000000000024 1.3322676295501878e-15" rpy="0 0 0"/>
    <mass value="0.3648087412503483"/>
    <inertia ixx="0.000317" iyy="2.7e-05" izz="0.000317" ixy="-0.0" iyz="0.0" ixz="-0.0"/>
  </inertial>
  <visual>
    <origin xyz="0.174006 0.05 -1.4942" rpy="0 0 0"/>
    <geometry>
      <mesh filename="package://walkie2_description/meshes/realsense_pitch.stl" scale="0.001 0.001 0.001"/>
    </geometry>
    <material name="silver"/>
  </visual>
  <collision>
    <origin xyz="0.174006 0.05 -1.4942" rpy="0 0 0"/>
    <geometry>
      <mesh filename="package://walkie2_description/meshes/realsense_pitch.stl" scale="0.001 0.001 0.001"/>
    </geometry>
  </collision>
</link>

<joint name="right_wheel_joint" type="continuous">
  <origin xyz="0.0 0.194 0.098" rpy="0 0 0"/>
  <parent link="base_link"/>
  <child link="right_wheel"/>
  <axis xyz="0.0 1.0 0.0"/>
</joint>

<joint name="left_wheel_joint" type="continuous">
  <origin xyz="0.0 -0.194 0.098" rpy="0 0 0"/>
  <parent link="base_link"/>
  <child link="left_wheel"/>
  <axis xyz="0.0 -1.0 0.0"/>
</joint>

<joint name="hokuyo_joint" type="fixed">
  <origin xyz="0.197 0.0 0.1955" rpy="0 0 0"/>
  <parent link="base_link"/>
  <child link="hokuyo"/>
</joint>

<joint name="base_cr3_joint" type="prismatic">
  <origin xyz="-0.016306 0.0 0.7855" rpy="0 0 0"/>
  <parent link="base_link"/>
  <child link="base_cr3"/>
  <axis xyz="0.0 0.0 1.0"/>
  <limit upper="0.0" lower="0.0" effort="100" velocity="100"/>
</joint>

<joint name="realsense_yaw_joint" type="revolute">
  <origin xyz="-0.189306 0.0 1.463" rpy="0 0 0"/>
  <parent link="base_link"/>
  <child link="realsense_pitch"/>
  <axis xyz="0.0 0.0 1.0"/>
  <limit effort="1000" lower="-1.57" upper="1.57" velocity="0.2"/>
</joint>

<joint name="realsense_pitch_joint" type="revolute">
  <origin xyz="0.00 0.00 0.0175" rpy="0 0 0"/>
  <parent link="realsense_pitch"/>
  <child link="realsense_yaw"/>
  <axis xyz="0.0 1.0 0.0"/>
  <limit effort="1000" lower="-1.57" upper="1.57" velocity="0.2"/>
</joint>

<joint name="imu_joint" type="fixed">
    <parent link="base_link"/>
    <child link="imu_link"/>
    <origin xyz="0 0 0" rpy="0 0 0"/>
</joint>

<link name="imu_link"/>

<xacro:cr3_robot parent_link="base_cr3"/>

</robot>